<?xml version="1.0" ?>
<!-- =================================================================================== -->
<!-- |    This document was autogenerated by xacro from quadbot.xacro                  | -->
<!-- |    EDITING THIS FILE BY HAND IS NOT RECOMMENDED                                 | -->
<!-- =================================================================================== -->
<robot name="URDF">
  <!-- <gazebo>
  <plugin filename="libgazebo_ros2_control.so" name="gazebo_ros2_control">
    <robot_param>robot_description</robot_param>
    <robot_param_node>robot_state_publisher</robot_param_node>
  </plugin>
</gazebo> -->
  <gazebo reference="base_link">
    <material>Gazebo/Silver</material>
    <mu1>0.2</mu1>
    <mu2>0.2</mu2>
    <selfCollide>true</selfCollide>
    <gravity>true</gravity>
  </gazebo>
  <gazebo reference="shoulder_RF_1">
    <material>Gazebo/Silver</material>
    <mu1>0.2</mu1>
    <mu2>0.2</mu2>
    <selfCollide>true</selfCollide>
  </gazebo>
  <gazebo reference="arm_foot_RF_1">
    <material>Gazebo/Silver</material>
    <mu1>0.2</mu1>
    <mu2>0.2</mu2>
    <selfCollide>true</selfCollide>
  </gazebo>
  <gazebo reference="arm_main_RF_1">
    <material>Gazebo/Silver</material>
    <mu1>0.2</mu1>
    <mu2>0.2</mu2>
    <selfCollide>true</selfCollide>
  </gazebo>
  <gazebo reference="arm_crank_RF_1">
    <material>Gazebo/Silver</material>
    <mu1>0.2</mu1>
    <mu2>0.2</mu2>
    <selfCollide>true</selfCollide>
  </gazebo>
  <gazebo reference="arm_link_RF_1">
    <material>Gazebo/Silver</material>
    <mu1>0.2</mu1>
    <mu2>0.2</mu2>
    <selfCollide>true</selfCollide>
  </gazebo>
  <gazebo reference="arm_lower_RF_1">
    <material>Gazebo/Silver</material>
    <mu1>0.2</mu1>
    <mu2>0.2</mu2>
    <selfCollide>true</selfCollide>
  </gazebo>
  <link name="base_link">
    <inertial>
      <origin rpy="0 0 0" xyz="0.00014024235087096401 -0.0003890538127367371 -0.019060892954127925"/>
      <mass value="0.5621563017705747"/>
      <inertia ixx="0.001155" ixy="4e-06" ixz="-2.4e-05" iyy="0.00653" iyz="2e-06" izz="0.006946"/>
    </inertial>
    <visual>
      <origin rpy="0 0 0" xyz="0 0 0"/>
      <geometry>
        <mesh filename="/home/tomasz/dev/QuadBotNG/sim/meshes/base_link.stl" scale="0.001 0.001 0.001"/>
      </geometry>
      <material name="silver"/>
    </visual>
    <collision>
      <origin rpy="0 0 0" xyz="0 0 0"/>
      <geometry>
        <mesh filename="/home/tomasz/dev/QuadBotNG/sim/meshes/base_link_c.stl" scale="0.001 0.001 0.001"/>
      </geometry>
    </collision>
  </link>
  <link name="drives_1">
    <inertial>
      <origin rpy="0 0 0" xyz="-0.03951765517329959 1.2719094139211486e-09 -0.012055286127708453"/>
      <mass value="3.702587577963783"/>
      <inertia ixx="0.008603" ixy="0.0" ixz="-0.0" iyy="0.056229" iyz="0.0" izz="0.062893"/>
    </inertial>
    <visual>
      <origin rpy="0 0 0" xyz="-0.039505 -0.0 -0.018083"/>
      <geometry>
        <mesh filename="/home/tomasz/dev/QuadBotNG/sim/meshes/drives_1.stl" scale="0.001 0.001 0.001"/>
      </geometry>
      <material name="silver"/>
    </visual>
    <!-- <collision>
    <origin xyz="-0.039505 -0.0 -0.018083" rpy="0 0 0"/>
    <geometry>
      <mesh filename="package://URDF_description/meshes/drives_1.stl" scale="0.001 0.001 0.001"/>
    </geometry>
  </collision> -->
  </link>
  <link name="shoulder_RF_1">
    <inertial>
      <origin rpy="0 0 0" xyz="0.07305887126794519 -0.006366818449876278 1.737939750193092e-05"/>
      <mass value="0.0687982302950686"/>
      <inertia ixx="4.5e-05" ixy="7e-06" ixz="0.0" iyy="4.9e-05" iyz="0.0" izz="5e-05"/>
    </inertial>
    <visual>
      <origin rpy="0 0 0" xyz="-0.039006 0.053 -0.0"/>
      <geometry>
        <mesh filename="/home/tomasz/dev/QuadBotNG/sim/meshes/shoulder_RF_1.stl" scale="0.001 0.001 0.001"/>
      </geometry>
      <material name="silver"/>
    </visual>
    <collision>
      <origin rpy="0 0 0" xyz="-0.039006 0.053 -0.0"/>
      <geometry>
        <mesh filename="/home/tomasz/dev/QuadBotNG/sim/meshes/shoulder_RF_1_c.stl" scale="0.001 0.001 0.001"/>
      </geometry>
    </collision>
  </link>
  <link name="arm_main_RF_1">
    <inertial>
      <origin rpy="0 0 0" xyz="-0.004247618304285272 -0.014187952596475387 -0.04886253447598682"/>
      <mass value="0.047281594844868054"/>
      <inertia ixx="7.8e-05" ixy="-0.0" ixz="2e-06" iyy="7.7e-05" iyz="-2e-06" izz="6e-06"/>
    </inertial>
    <visual>
      <origin rpy="0 0 0" xyz="-0.118706 0.0875 -0.0"/>
      <geometry>
        <mesh filename="/home/tomasz/dev/QuadBotNG/sim/meshes/arm_main_RF_1.stl" scale="0.001 0.001 0.001"/>
      </geometry>
      <material name="silver"/>
    </visual>
    <collision>
      <origin rpy="0 0 0" xyz="-0.118706 0.0875 -0.0"/>
      <geometry>
        <mesh filename="/home/tomasz/dev/QuadBotNG/sim/meshes/arm_main_RF_1_c.stl" scale="0.001 0.001 0.001"/>
      </geometry>
    </collision>
  </link>
  <link name="arm_crank_RF_1">
    <inertial>
      <origin rpy="0 0 0" xyz="0.01870365879895089 -0.01385715444565519 9.569436468071744e-05"/>
      <mass value="0.007002755420396213"/>
      <inertia ixx="0.0" ixy="0.0" ixz="-0.0" iyy="2e-06" iyz="0.0" izz="2e-06"/>
    </inertial>
    <visual>
      <origin rpy="0 0 0" xyz="-0.118706 0.0875 -0.0"/>
      <geometry>
        <mesh filename="/home/tomasz/dev/QuadBotNG/sim/meshes/arm_crank_RF_1.stl" scale="0.001 0.001 0.001"/>
      </geometry>
      <material name="silver"/>
    </visual>
    <!-- <collision>
    <origin xyz="-0.118706 0.0875 -0.0" rpy="0 0 0"/>
    <geometry>
      <mesh filename="/home/tomasz/dev/QuadBotNG/sim/meshes/arm_crank_${prefix}_1.stl"
      scale="0.001 0.001 0.001"/>
    </geometry>
    <surface>
      <contact>
        <collide_bitmask>0x02</collide_bitmask>
      </contact>
    </surface>
  </collision> -->
  </link>
  <link name="arm_link_RF_1">
    <inertial>
      <origin rpy="0 0 0" xyz="0.00114096544972489 -0.0013691619442786351 -0.05890529754921636"/>
      <mass value="0.0331145638504204"/>
      <inertia ixx="4.4e-05" ixy="-0.0" ixz="-1e-06" iyy="4.3e-05" iyz="0.0" izz="4e-06"/>
    </inertial>
    <visual>
      <origin rpy="0 0 0" xyz="-0.153706 0.1026 -0.0"/>
      <geometry>
        <mesh filename="/home/tomasz/dev/QuadBotNG/sim/meshes/arm_link_RF_1.stl" scale="0.001 0.001 0.001"/>
      </geometry>
      <material name="silver"/>
    </visual>
    <!-- <collision>
    <origin xyz="-0.153706 0.1026 -0.0" rpy="0 0 0"/>
    <geometry>
      <mesh filename="/home/tomasz/dev/QuadBotNG/sim/meshes/arm_link_${prefix}_1.stl"
      scale="0.001 0.001 0.001"/>
    </geometry>
    <surface>
      <contact>
        <collide_bitmask>0x04</collide_bitmask>
      </contact>
    </surface>
  </collision>
   -->
  </link>
  <link name="arm_lower_RF_1">
    <inertial>
      <origin rpy="0 0 0" xyz="0.06322127393693497 4.99720667845871e-07 -0.0019199942850988"/>
      <mass value="0.03998924644154324"/>
      <inertia ixx="3e-06" ixy="-0.0" ixz="-2e-06" iyy="6e-05" iyz="0.0" izz="5.9e-05"/>
    </inertial>
    <visual>
      <origin rpy="0 0 0" xyz="-0.118702 0.1026 0.119915"/>
      <geometry>
        <mesh filename="/home/tomasz/dev/QuadBotNG/sim/meshes/arm_lower_RF_1.stl" scale="0.001 0.001 0.001"/>
      </geometry>
      <material name="silver"/>
    </visual>
    <collision>
      <origin rpy="0 0 0" xyz="-0.118702 0.1026 0.119915"/>
      <geometry>
        <mesh filename="/home/tomasz/dev/QuadBotNG/sim/meshes/arm_lower_RF_1_c.stl" scale="0.001 0.001 0.001"/>
      </geometry>
      <surface>
        <contact>
          <collide_bitmask>0x08</collide_bitmask>
        </contact>
      </surface>
    </collision>
  </link>
  <joint name="base_to_shoulder_RF" type="continuous">
    <origin rpy="0 0 0" xyz="0.039006 -0.053 0.0"/>
    <parent link="base_link"/>
    <child link="shoulder_RF_1"/>
    <axis xyz="1.0 -0.0 -0.0"/>
  </joint>
  <joint name="shoulder_to_main_RF" type="continuous">
    <origin rpy="0 0 0" xyz="0.0797 -0.0345 0.0"/>
    <parent link="shoulder_RF_1"/>
    <child link="arm_main_RF_1"/>
    <axis xyz="0.0 1.0 0.0"/>
  </joint>
  <joint name="shoulder_to_crank_RF" type="continuous">
    <origin rpy="0 0 0" xyz="0.0797 -0.0345 0.0"/>
    <parent link="shoulder_RF_1"/>
    <child link="arm_crank_RF_1"/>
    <axis xyz="0.0 1.0 0.0"/>
  </joint>
  <joint name="crank_to_link_RF" type="continuous">
    <origin rpy="0 0 0" xyz="0.035 -0.0151 0.0"/>
    <parent link="arm_crank_RF_1"/>
    <child link="arm_link_RF_1"/>
    <axis xyz="0.0 -1.0 0.0"/>
  </joint>
  <joint name="main_to_lower_RF" type="continuous">
    <origin rpy="0 0 0" xyz="0.0 -0.0151 -0.12"/>
    <parent link="arm_main_RF_1"/>
    <child link="arm_lower_RF_1"/>
    <axis xyz="0.0 1.0 0.0"/>
  </joint>
  <transmission name="main_trans_RF">
    <type>transmission_interface/DifferenceTransmission</type>
    <actuator name="main_motor_RF">
      <role>actuator1</role>
      <mechanicalReduction>1.5</mechanicalReduction>
    </actuator>
    <actuator name="shoulder_motor_RF">
      <role>actuator2</role>
      <mechanicalReduction>2.25</mechanicalReduction>
    </actuator>
  </transmission>
  <transmission name="crank_trans_RF">
    <type>transmission_interface/DifferenceTransmission</type>
    <actuator name="crank_motor_RF">
      <role>actuator1</role>
      <mechanicalReduction>1.5</mechanicalReduction>
    </actuator>
    <actuator name="shoulder_motor_RF">
      <role>actuator2</role>
      <mechanicalReduction>2.25</mechanicalReduction>
    </actuator>
  </transmission>
  <transmission name="crank_trans_RF">
    <type>transmission_interface/SimpleTransmission</type>
    <actuator name="shoulder_motor_RF">
      <mechanicalReduction>1.5</mechanicalReduction>
    </actuator>
  </transmission>
  <gazebo>
    <joint name="link_to_lower_RF" type="ball">
      <parent>arm_link_RF_1</parent>
      <child>arm_lower_RF_1</child>
      <axis>
        <xyz>0 1 0</xyz>
      </axis>
      <pose relative_to="arm_link_RF_1">0.0 0.0 -0.12 0.0 0.0 0.0</pose>
    </joint>
  </gazebo>
  <link name="shoulder_LF_1">
    <inertial>
      <origin rpy="0 0 0" xyz="0.07305887126794519 0.006366818449876278 1.737939750193092e-05"/>
      <mass value="0.0687982302950686"/>
      <inertia ixx="4.5e-05" ixy="-7e-06" ixz="0.0" iyy="4.9e-05" iyz="0.0" izz="5e-05"/>
    </inertial>
    <visual>
      <origin rpy="0 0 0" xyz="-0.039006 -0.053 -0.0"/>
      <geometry>
        <mesh filename="/home/tomasz/dev/QuadBotNG/sim/meshes/shoulder_LF_1.stl" scale="0.001 0.001 0.001"/>
      </geometry>
      <material name="silver"/>
    </visual>
    <collision>
      <origin rpy="0 0 0" xyz="-0.039006 -0.053 -0.0"/>
      <geometry>
        <mesh filename="/home/tomasz/dev/QuadBotNG/sim/meshes/shoulder_LF_1_c.stl" scale="0.001 0.001 0.001"/>
      </geometry>
    </collision>
  </link>
  <link name="arm_main_LF_1">
    <inertial>
      <origin rpy="0 0 0" xyz="-0.004247618304285272 0.014187952596475387 -0.04886253447598682"/>
      <mass value="0.047281594844868054"/>
      <inertia ixx="7.8e-05" ixy="-0.0" ixz="2e-06" iyy="7.7e-05" iyz="2e-06" izz="6e-06"/>
    </inertial>
    <visual>
      <origin rpy="0 0 0" xyz="-0.118706 -0.0875 -0.0"/>
      <geometry>
        <mesh filename="/home/tomasz/dev/QuadBotNG/sim/meshes/arm_main_LF_1.stl" scale="0.001 0.001 0.001"/>
      </geometry>
      <material name="silver"/>
    </visual>
    <collision>
      <origin rpy="0 0 0" xyz="-0.118706 -0.0875 -0.0"/>
      <geometry>
        <mesh filename="/home/tomasz/dev/QuadBotNG/sim/meshes/arm_main_LF_1_c.stl" scale="0.001 0.001 0.001"/>
      </geometry>
    </collision>
  </link>
  <link name="arm_crank_LF_1">
    <inertial>
      <origin rpy="0 0 0" xyz="0.01870365879895089 0.01385715444565519 9.569436468071744e-05"/>
      <mass value="0.007002755420396213"/>
      <inertia ixx="0.0" ixy="0.0" ixz="-0.0" iyy="2e-06" iyz="0.0" izz="2e-06"/>
    </inertial>
    <visual>
      <origin rpy="0 0 0" xyz="-0.118706 -0.0875 -0.0"/>
      <geometry>
        <mesh filename="/home/tomasz/dev/QuadBotNG/sim/meshes/arm_crank_LF_1.stl" scale="0.001 0.001 0.001"/>
      </geometry>
      <material name="silver"/>
    </visual>
    <!-- <collision>
    <origin xyz="-0.118706 0.0875 -0.0" rpy="0 0 0"/>
    <geometry>
      <mesh filename="/home/tomasz/dev/QuadBotNG/sim/meshes/arm_crank_${prefix}_1.stl"
      scale="0.001 0.001 0.001"/>
    </geometry>
    <surface>
      <contact>
        <collide_bitmask>0x02</collide_bitmask>
      </contact>
    </surface>
  </collision> -->
  </link>
  <link name="arm_link_LF_1">
    <inertial>
      <origin rpy="0 0 0" xyz="0.00114096544972489 0.0013691619442786351 -0.05890529754921636"/>
      <mass value="0.0331145638504204"/>
      <inertia ixx="4.4e-05" ixy="-0.0" ixz="-1e-06" iyy="4.3e-05" iyz="0.0" izz="4e-06"/>
    </inertial>
    <visual>
      <origin rpy="0 0 0" xyz="-0.153706 -0.1026 -0.0"/>
      <geometry>
        <mesh filename="/home/tomasz/dev/QuadBotNG/sim/meshes/arm_link_LF_1.stl" scale="0.001 0.001 0.001"/>
      </geometry>
      <material name="silver"/>
    </visual>
    <!-- <collision>
    <origin xyz="-0.153706 0.1026 -0.0" rpy="0 0 0"/>
    <geometry>
      <mesh filename="/home/tomasz/dev/QuadBotNG/sim/meshes/arm_link_${prefix}_1.stl"
      scale="0.001 0.001 0.001"/>
    </geometry>
    <surface>
      <contact>
        <collide_bitmask>0x04</collide_bitmask>
      </contact>
    </surface>
  </collision>
   -->
  </link>
  <link name="arm_lower_LF_1">
    <inertial>
      <origin rpy="0 0 0" xyz="0.06322127393693497 -4.99720667845871e-07 -0.0019199942850988"/>
      <mass value="0.03998924644154324"/>
      <inertia ixx="3e-06" ixy="-0.0" ixz="-2e-06" iyy="6e-05" iyz="0.0" izz="5.9e-05"/>
    </inertial>
    <visual>
      <origin rpy="0 0 0" xyz="-0.118702 -0.1026 0.119915"/>
      <geometry>
        <mesh filename="/home/tomasz/dev/QuadBotNG/sim/meshes/arm_lower_LF_1.stl" scale="0.001 0.001 0.001"/>
      </geometry>
      <material name="silver"/>
    </visual>
    <collision>
      <origin rpy="0 0 0" xyz="-0.118702 -0.1026 0.119915"/>
      <geometry>
        <mesh filename="/home/tomasz/dev/QuadBotNG/sim/meshes/arm_lower_LF_1_c.stl" scale="0.001 0.001 0.001"/>
      </geometry>
      <surface>
        <contact>
          <collide_bitmask>0x08</collide_bitmask>
        </contact>
      </surface>
    </collision>
  </link>
  <joint name="base_to_shoulder_LF" type="continuous">
    <origin rpy="0 0 0" xyz="0.039006 0.053 0.0"/>
    <parent link="base_link"/>
    <child link="shoulder_LF_1"/>
    <axis xyz="1.0 -0.0 -0.0"/>
  </joint>
  <joint name="shoulder_to_main_LF" type="continuous">
    <origin rpy="0 0 0" xyz="0.0797 0.0345 0.0"/>
    <parent link="shoulder_LF_1"/>
    <child link="arm_main_LF_1"/>
    <axis xyz="0.0 1.0 0.0"/>
  </joint>
  <joint name="shoulder_to_crank_LF" type="continuous">
    <origin rpy="0 0 0" xyz="0.0797 0.0345 0.0"/>
    <parent link="shoulder_LF_1"/>
    <child link="arm_crank_LF_1"/>
    <axis xyz="0.0 1.0 0.0"/>
  </joint>
  <joint name="crank_to_link_LF" type="continuous">
    <origin rpy="0 0 0" xyz="0.035 0.0151 0.0"/>
    <parent link="arm_crank_LF_1"/>
    <child link="arm_link_LF_1"/>
    <axis xyz="0.0 -1.0 0.0"/>
  </joint>
  <joint name="main_to_lower_LF" type="continuous">
    <origin rpy="0 0 0" xyz="0.0 0.0151 -0.12"/>
    <parent link="arm_main_LF_1"/>
    <child link="arm_lower_LF_1"/>
    <axis xyz="0.0 1.0 0.0"/>
  </joint>
  <transmission name="main_trans_LF">
    <type>transmission_interface/DifferenceTransmission</type>
    <actuator name="main_motor_LF">
      <role>actuator1</role>
      <mechanicalReduction>1.5</mechanicalReduction>
    </actuator>
    <actuator name="shoulder_motor_LF">
      <role>actuator2</role>
      <mechanicalReduction>2.25</mechanicalReduction>
    </actuator>
  </transmission>
  <transmission name="crank_trans_LF">
    <type>transmission_interface/DifferenceTransmission</type>
    <actuator name="crank_motor_LF">
      <role>actuator1</role>
      <mechanicalReduction>1.5</mechanicalReduction>
    </actuator>
    <actuator name="shoulder_motor_LF">
      <role>actuator2</role>
      <mechanicalReduction>2.25</mechanicalReduction>
    </actuator>
  </transmission>
  <transmission name="crank_trans_LF">
    <type>transmission_interface/SimpleTransmission</type>
    <actuator name="shoulder_motor_LF">
      <mechanicalReduction>1.5</mechanicalReduction>
    </actuator>
  </transmission>
  <gazebo>
    <joint name="link_to_lower_LF" type="ball">
      <parent>arm_link_LF_1</parent>
      <child>arm_lower_LF_1</child>
      <axis>
        <xyz>0 1 0</xyz>
      </axis>
      <pose relative_to="arm_link_LF_1">0.0 0.0 -0.12 0.0 0.0 0.0</pose>
    </joint>
  </gazebo>
  <link name="shoulder_RB_1">
    <inertial>
      <origin rpy="0 0 0" xyz="0.07305887126794519 -0.006366818449876278 1.737939750193092e-05"/>
      <mass value="0.0687982302950686"/>
      <inertia ixx="4.5e-05" ixy="7e-06" ixz="0.0" iyy="4.9e-05" iyz="0.0" izz="5e-05"/>
    </inertial>
    <visual>
      <origin rpy="0 0 0" xyz="-0.039006 0.053 -0.0"/>
      <geometry>
        <mesh filename="/home/tomasz/dev/QuadBotNG/sim/meshes/shoulder_RF_1.stl" scale="0.001 0.001 0.001"/>
      </geometry>
      <material name="silver"/>
    </visual>
    <collision>
      <origin rpy="0 0 0" xyz="-0.039006 0.053 -0.0"/>
      <geometry>
        <mesh filename="/home/tomasz/dev/QuadBotNG/sim/meshes/shoulder_RF_1_c.stl" scale="0.001 0.001 0.001"/>
      </geometry>
    </collision>
  </link>
  <link name="arm_main_RB_1">
    <inertial>
      <origin rpy="0 0 0" xyz="-0.004247618304285272 -0.014187952596475387 -0.04886253447598682"/>
      <mass value="0.047281594844868054"/>
      <inertia ixx="7.8e-05" ixy="-0.0" ixz="2e-06" iyy="7.7e-05" iyz="-2e-06" izz="6e-06"/>
    </inertial>
    <visual>
      <origin rpy="0 0 0" xyz="-0.118706 0.0875 -0.0"/>
      <geometry>
        <mesh filename="/home/tomasz/dev/QuadBotNG/sim/meshes/arm_main_RF_1.stl" scale="0.001 0.001 0.001"/>
      </geometry>
      <material name="silver"/>
    </visual>
    <collision>
      <origin rpy="0 0 0" xyz="-0.118706 0.0875 -0.0"/>
      <geometry>
        <mesh filename="/home/tomasz/dev/QuadBotNG/sim/meshes/arm_main_RF_1_c.stl" scale="0.001 0.001 0.001"/>
      </geometry>
    </collision>
  </link>
  <link name="arm_crank_RB_1">
    <inertial>
      <origin rpy="0 0 0" xyz="0.01870365879895089 -0.01385715444565519 9.569436468071744e-05"/>
      <mass value="0.007002755420396213"/>
      <inertia ixx="0.0" ixy="0.0" ixz="-0.0" iyy="2e-06" iyz="0.0" izz="2e-06"/>
    </inertial>
    <visual>
      <origin rpy="0 0 0" xyz="-0.118706 0.0875 -0.0"/>
      <geometry>
        <mesh filename="/home/tomasz/dev/QuadBotNG/sim/meshes/arm_crank_RF_1.stl" scale="0.001 0.001 0.001"/>
      </geometry>
      <material name="silver"/>
    </visual>
    <!-- <collision>
    <origin xyz="-0.118706 0.0875 -0.0" rpy="0 0 0"/>
    <geometry>
      <mesh filename="/home/tomasz/dev/QuadBotNG/sim/meshes/arm_crank_${prefix}_1.stl"
      scale="0.001 0.001 0.001"/>
    </geometry>
    <surface>
      <contact>
        <collide_bitmask>0x02</collide_bitmask>
      </contact>
    </surface>
  </collision> -->
  </link>
  <link name="arm_link_RB_1">
    <inertial>
      <origin rpy="0 0 0" xyz="0.00114096544972489 -0.0013691619442786351 -0.05890529754921636"/>
      <mass value="0.0331145638504204"/>
      <inertia ixx="4.4e-05" ixy="-0.0" ixz="-1e-06" iyy="4.3e-05" iyz="0.0" izz="4e-06"/>
    </inertial>
    <visual>
      <origin rpy="0 0 0" xyz="-0.153706 0.1026 -0.0"/>
      <geometry>
        <mesh filename="/home/tomasz/dev/QuadBotNG/sim/meshes/arm_link_RF_1.stl" scale="0.001 0.001 0.001"/>
      </geometry>
      <material name="silver"/>
    </visual>
    <!-- <collision>
    <origin xyz="-0.153706 0.1026 -0.0" rpy="0 0 0"/>
    <geometry>
      <mesh filename="/home/tomasz/dev/QuadBotNG/sim/meshes/arm_link_${prefix}_1.stl"
      scale="0.001 0.001 0.001"/>
    </geometry>
    <surface>
      <contact>
        <collide_bitmask>0x04</collide_bitmask>
      </contact>
    </surface>
  </collision>
   -->
  </link>
  <link name="arm_lower_RB_1">
    <inertial>
      <origin rpy="0 0 0" xyz="0.06322127393693497 4.99720667845871e-07 -0.0019199942850988"/>
      <mass value="0.03998924644154324"/>
      <inertia ixx="3e-06" ixy="-0.0" ixz="-2e-06" iyy="6e-05" iyz="0.0" izz="5.9e-05"/>
    </inertial>
    <visual>
      <origin rpy="0 0 0" xyz="-0.118702 0.1026 0.119915"/>
      <geometry>
        <mesh filename="/home/tomasz/dev/QuadBotNG/sim/meshes/arm_lower_RF_1.stl" scale="0.001 0.001 0.001"/>
      </geometry>
      <material name="silver"/>
    </visual>
    <collision>
      <origin rpy="0 0 0" xyz="-0.118702 0.1026 0.119915"/>
      <geometry>
        <mesh filename="/home/tomasz/dev/QuadBotNG/sim/meshes/arm_lower_RF_1_c.stl" scale="0.001 0.001 0.001"/>
      </geometry>
      <surface>
        <contact>
          <collide_bitmask>0x08</collide_bitmask>
        </contact>
      </surface>
    </collision>
  </link>
  <joint name="base_to_shoulder_RB" type="continuous">
    <origin rpy="0 0 0" xyz="-0.195006 -0.053 0.0"/>
    <parent link="base_link"/>
    <child link="shoulder_RB_1"/>
    <axis xyz="1.0 -0.0 -0.0"/>
  </joint>
  <joint name="shoulder_to_main_RB" type="continuous">
    <origin rpy="0 0 0" xyz="0.0797 -0.0345 0.0"/>
    <parent link="shoulder_RB_1"/>
    <child link="arm_main_RB_1"/>
    <axis xyz="0.0 1.0 0.0"/>
  </joint>
  <joint name="shoulder_to_crank_RB" type="continuous">
    <origin rpy="0 0 0" xyz="0.0797 -0.0345 0.0"/>
    <parent link="shoulder_RB_1"/>
    <child link="arm_crank_RB_1"/>
    <axis xyz="0.0 1.0 0.0"/>
  </joint>
  <joint name="crank_to_link_RB" type="continuous">
    <origin rpy="0 0 0" xyz="0.035 -0.0151 0.0"/>
    <parent link="arm_crank_RB_1"/>
    <child link="arm_link_RB_1"/>
    <axis xyz="0.0 -1.0 0.0"/>
  </joint>
  <joint name="main_to_lower_RB" type="continuous">
    <origin rpy="0 0 0" xyz="0.0 -0.0151 -0.12"/>
    <parent link="arm_main_RB_1"/>
    <child link="arm_lower_RB_1"/>
    <axis xyz="0.0 1.0 0.0"/>
  </joint>
  <transmission name="main_trans_RB">
    <type>transmission_interface/DifferenceTransmission</type>
    <actuator name="main_motor_RB">
      <role>actuator1</role>
      <mechanicalReduction>1.5</mechanicalReduction>
    </actuator>
    <actuator name="shoulder_motor_RB">
      <role>actuator2</role>
      <mechanicalReduction>2.25</mechanicalReduction>
    </actuator>
  </transmission>
  <transmission name="crank_trans_RB">
    <type>transmission_interface/DifferenceTransmission</type>
    <actuator name="crank_motor_RB">
      <role>actuator1</role>
      <mechanicalReduction>1.5</mechanicalReduction>
    </actuator>
    <actuator name="shoulder_motor_RB">
      <role>actuator2</role>
      <mechanicalReduction>2.25</mechanicalReduction>
    </actuator>
  </transmission>
  <transmission name="crank_trans_RB">
    <type>transmission_interface/SimpleTransmission</type>
    <actuator name="shoulder_motor_RB">
      <mechanicalReduction>1.5</mechanicalReduction>
    </actuator>
  </transmission>
  <gazebo>
    <joint name="link_to_lower_RB" type="ball">
      <parent>arm_link_RB_1</parent>
      <child>arm_lower_RB_1</child>
      <axis>
        <xyz>0 1 0</xyz>
      </axis>
      <pose relative_to="arm_link_RB_1">0.0 0.0 -0.12 0.0 0.0 0.0</pose>
    </joint>
  </gazebo>
  <link name="shoulder_LB_1">
    <inertial>
      <origin rpy="0 0 0" xyz="0.07305887126794519 0.006366818449876278 1.737939750193092e-05"/>
      <mass value="0.0687982302950686"/>
      <inertia ixx="4.5e-05" ixy="-7e-06" ixz="0.0" iyy="4.9e-05" iyz="0.0" izz="5e-05"/>
    </inertial>
    <visual>
      <origin rpy="0 0 0" xyz="-0.039006 -0.053 -0.0"/>
      <geometry>
        <mesh filename="/home/tomasz/dev/QuadBotNG/sim/meshes/shoulder_LF_1.stl" scale="0.001 0.001 0.001"/>
      </geometry>
      <material name="silver"/>
    </visual>
    <collision>
      <origin rpy="0 0 0" xyz="-0.039006 -0.053 -0.0"/>
      <geometry>
        <mesh filename="/home/tomasz/dev/QuadBotNG/sim/meshes/shoulder_LF_1_c.stl" scale="0.001 0.001 0.001"/>
      </geometry>
    </collision>
  </link>
  <link name="arm_main_LB_1">
    <inertial>
      <origin rpy="0 0 0" xyz="-0.004247618304285272 0.014187952596475387 -0.04886253447598682"/>
      <mass value="0.047281594844868054"/>
      <inertia ixx="7.8e-05" ixy="-0.0" ixz="2e-06" iyy="7.7e-05" iyz="2e-06" izz="6e-06"/>
    </inertial>
    <visual>
      <origin rpy="0 0 0" xyz="-0.118706 -0.0875 -0.0"/>
      <geometry>
        <mesh filename="/home/tomasz/dev/QuadBotNG/sim/meshes/arm_main_LF_1.stl" scale="0.001 0.001 0.001"/>
      </geometry>
      <material name="silver"/>
    </visual>
    <collision>
      <origin rpy="0 0 0" xyz="-0.118706 -0.0875 -0.0"/>
      <geometry>
        <mesh filename="/home/tomasz/dev/QuadBotNG/sim/meshes/arm_main_LF_1_c.stl" scale="0.001 0.001 0.001"/>
      </geometry>
    </collision>
  </link>
  <link name="arm_crank_LB_1">
    <inertial>
      <origin rpy="0 0 0" xyz="0.01870365879895089 0.01385715444565519 9.569436468071744e-05"/>
      <mass value="0.007002755420396213"/>
      <inertia ixx="0.0" ixy="0.0" ixz="-0.0" iyy="2e-06" iyz="0.0" izz="2e-06"/>
    </inertial>
    <visual>
      <origin rpy="0 0 0" xyz="-0.118706 -0.0875 -0.0"/>
      <geometry>
        <mesh filename="/home/tomasz/dev/QuadBotNG/sim/meshes/arm_crank_LF_1.stl" scale="0.001 0.001 0.001"/>
      </geometry>
      <material name="silver"/>
    </visual>
    <!-- <collision>
    <origin xyz="-0.118706 0.0875 -0.0" rpy="0 0 0"/>
    <geometry>
      <mesh filename="/home/tomasz/dev/QuadBotNG/sim/meshes/arm_crank_${prefix}_1.stl"
      scale="0.001 0.001 0.001"/>
    </geometry>
    <surface>
      <contact>
        <collide_bitmask>0x02</collide_bitmask>
      </contact>
    </surface>
  </collision> -->
  </link>
  <link name="arm_link_LB_1">
    <inertial>
      <origin rpy="0 0 0" xyz="0.00114096544972489 0.0013691619442786351 -0.05890529754921636"/>
      <mass value="0.0331145638504204"/>
      <inertia ixx="4.4e-05" ixy="-0.0" ixz="-1e-06" iyy="4.3e-05" iyz="0.0" izz="4e-06"/>
    </inertial>
    <visual>
      <origin rpy="0 0 0" xyz="-0.153706 -0.1026 -0.0"/>
      <geometry>
        <mesh filename="/home/tomasz/dev/QuadBotNG/sim/meshes/arm_link_LF_1.stl" scale="0.001 0.001 0.001"/>
      </geometry>
      <material name="silver"/>
    </visual>
    <!-- <collision>
    <origin xyz="-0.153706 0.1026 -0.0" rpy="0 0 0"/>
    <geometry>
      <mesh filename="/home/tomasz/dev/QuadBotNG/sim/meshes/arm_link_${prefix}_1.stl"
      scale="0.001 0.001 0.001"/>
    </geometry>
    <surface>
      <contact>
        <collide_bitmask>0x04</collide_bitmask>
      </contact>
    </surface>
  </collision>
   -->
  </link>
  <link name="arm_lower_LB_1">
    <inertial>
      <origin rpy="0 0 0" xyz="0.06322127393693497 -4.99720667845871e-07 -0.0019199942850988"/>
      <mass value="0.03998924644154324"/>
      <inertia ixx="3e-06" ixy="-0.0" ixz="-2e-06" iyy="6e-05" iyz="0.0" izz="5.9e-05"/>
    </inertial>
    <visual>
      <origin rpy="0 0 0" xyz="-0.118702 -0.1026 0.119915"/>
      <geometry>
        <mesh filename="/home/tomasz/dev/QuadBotNG/sim/meshes/arm_lower_LF_1.stl" scale="0.001 0.001 0.001"/>
      </geometry>
      <material name="silver"/>
    </visual>
    <collision>
      <origin rpy="0 0 0" xyz="-0.118702 -0.1026 0.119915"/>
      <geometry>
        <mesh filename="/home/tomasz/dev/QuadBotNG/sim/meshes/arm_lower_LF_1_c.stl" scale="0.001 0.001 0.001"/>
      </geometry>
      <surface>
        <contact>
          <collide_bitmask>0x08</collide_bitmask>
        </contact>
      </surface>
    </collision>
  </link>
  <joint name="base_to_shoulder_LB" type="continuous">
    <origin rpy="0 0 0" xyz="-0.195006 0.053 0.0"/>
    <parent link="base_link"/>
    <child link="shoulder_LB_1"/>
    <axis xyz="1.0 -0.0 -0.0"/>
  </joint>
  <joint name="shoulder_to_main_LB" type="continuous">
    <origin rpy="0 0 0" xyz="0.0797 0.0345 0.0"/>
    <parent link="shoulder_LB_1"/>
    <child link="arm_main_LB_1"/>
    <axis xyz="0.0 1.0 0.0"/>
  </joint>
  <joint name="shoulder_to_crank_LB" type="continuous">
    <origin rpy="0 0 0" xyz="0.0797 0.0345 0.0"/>
    <parent link="shoulder_LB_1"/>
    <child link="arm_crank_LB_1"/>
    <axis xyz="0.0 1.0 0.0"/>
  </joint>
  <joint name="crank_to_link_LB" type="continuous">
    <origin rpy="0 0 0" xyz="0.035 0.0151 0.0"/>
    <parent link="arm_crank_LB_1"/>
    <child link="arm_link_LB_1"/>
    <axis xyz="0.0 -1.0 0.0"/>
  </joint>
  <joint name="main_to_lower_LB" type="continuous">
    <origin rpy="0 0 0" xyz="0.0 0.0151 -0.12"/>
    <parent link="arm_main_LB_1"/>
    <child link="arm_lower_LB_1"/>
    <axis xyz="0.0 1.0 0.0"/>
  </joint>
  <transmission name="main_trans_LB">
    <type>transmission_interface/DifferenceTransmission</type>
    <actuator name="main_motor_LB">
      <role>actuator1</role>
      <mechanicalReduction>1.5</mechanicalReduction>
    </actuator>
    <actuator name="shoulder_motor_LB">
      <role>actuator2</role>
      <mechanicalReduction>2.25</mechanicalReduction>
    </actuator>
  </transmission>
  <transmission name="crank_trans_LB">
    <type>transmission_interface/DifferenceTransmission</type>
    <actuator name="crank_motor_LB">
      <role>actuator1</role>
      <mechanicalReduction>1.5</mechanicalReduction>
    </actuator>
    <actuator name="shoulder_motor_LB">
      <role>actuator2</role>
      <mechanicalReduction>2.25</mechanicalReduction>
    </actuator>
  </transmission>
  <transmission name="crank_trans_LB">
    <type>transmission_interface/SimpleTransmission</type>
    <actuator name="shoulder_motor_LB">
      <mechanicalReduction>1.5</mechanicalReduction>
    </actuator>
  </transmission>
  <gazebo>
    <joint name="link_to_lower_LB" type="ball">
      <parent>arm_link_LB_1</parent>
      <child>arm_lower_LB_1</child>
      <axis>
        <xyz>0 1 0</xyz>
      </axis>
      <pose relative_to="arm_link_LB_1">0.0 0.0 -0.12 0.0 0.0 0.0</pose>
    </joint>
  </gazebo>
  <joint name="base_to_drives" type="fixed">
    <origin rpy="0 0 0" xyz="0.039505 0.0 0.018083"/>
    <parent link="base_link"/>
    <child link="drives_1"/>
  </joint>
</robot>
